<?xml version='1.0' encoding='utf-8'?>
<robot xmlns:xacro="http://www.ros.org/wiki/xacro" name="omniseer" xmlns:gz="http://gazebosim.org/schema">
    <xacro:property name="min_vel" value="-50"/>
    <xacro:property name="max_vel" value="50"/>
    <xacro:property name="slip1" value="0.001"/>
    <xacro:property name="slip2" value="0.001"/>
    <xacro:property name="kp"   value="1e5"/>
    <xacro:property name="kd"   value="1.0"/>
    <xacro:property name="mu"   value="1.0"/>
    <xacro:property name="mu2"   value="0.05"/>
    <xacro:property name="body_rgba"   value="0.671 0.663 0.506 1.0"/>
    <xacro:property name="sensor_rgba" value="0.671 0.663 0.506 1.0"/>
    <xacro:property name="debug_rgba" value="1.0 0.0 0.0 1.0"/>
    <xacro:property name="wheel_radius" value="0.0485"/>
    <xacro:property name="wheel_width" value="0.0445"/>


    <xacro:macro name="wheel_transmission" params="joint">
        <transmission name="${joint}_tr">
            <type>transmission_interface/SimpleTransmission</type>
            <joint name="${joint}">
                <hardwareInterface>hardware_interface/VelocityJointInterface</hardwareInterface>
            </joint>
            <actuator name="${joint}_motor">
                <hardwareInterface>hardware_interface/VelocityJointInterface</hardwareInterface>
                <mechanicalReduction>1</mechanicalReduction>
            </actuator>
        </transmission>
    </xacro:macro>

    <xacro:wheel_transmission joint="chassis_fl_wheel_joint"/>
    <xacro:wheel_transmission joint="chassis_fr_wheel_joint"/>
    <xacro:wheel_transmission joint="chassis_bl_wheel_joint"/>
    <xacro:wheel_transmission joint="chassis_br_wheel_joint"/>

    <!-- Links -->

    <link name="fl_wheel">
        <inertial>
            <origin xyz="1.7993153278439422e-09 0 0" rpy="0.0 -0.0 0.0" />
            <mass value="0.1449437592188408" />
            <inertia ixx="0.00010654272201079539" iyy="0.00010654272201080037" izz="0.00017047197881125639" ixy="-4.7460314825842516e-20" iyz="-5.1880768019325896e-20" ixz="0.0" />
        </inertial>
        <visual name="fl_wheel_visual">
            <origin xyz="1.7993155232431945e-09 0 0" rpy="1.5707963267948968 1.2281842209915656e-15 3.1554436208840444e-30" />
            <geometry>
                <mesh filename="package://omniseer_description/meshes/fl_wheel.stl" scale="0.001 0.001 0.001" />
            </geometry>
            <material name='body_mat'>
                <color rgba="${body_rgba}"/>
            </material>
        </visual>
        <collision name="fl_wheel_collision">
            <origin xyz="1.7993155232431945e-09 0 0" rpy="0 1.2281842209915656e-15 3.1554436208840444e-30" />
            <geometry>
                <cylinder radius="${wheel_radius}" length="${wheel_width}"/>
            </geometry>
        </collision>
    </link>
    <link name="bl_wheel">
        <inertial>
            <origin xyz="-1.7993153278439422e-09 0 0" rpy="0.0 -0.0 0.0" />
            <mass value="0.1449437592188408" />
            <inertia ixx="0.00010654272201079539" iyy="0.0001065427220107995" izz="0.00017047197881125617" ixy="-4.7460314825842516e-20" iyz="-5.1880768019325896e-20" ixz="0.0" />
        </inertial>
        <visual name="bl_wheel_visual">
            <origin xyz="-1.7993151324446899e-09 0 0" rpy="1.5707963267948968 1.2281842209915656e-15 3.1554436208840444e-30" />
            <geometry>
                <mesh filename="package://omniseer_description/meshes/bl_wheel.stl" scale="0.001 0.001 0.001" />
            </geometry>
            <material name='body_mat'>
                <color rgba="${body_rgba}"/>
            </material>
        </visual>
        <collision name="bl_wheel_collision">
            <origin xyz="-1.7993151324446899e-09 0 0" rpy="0 1.2281842209915656e-15 3.1554436208840444e-30" />
            <geometry>
                <cylinder radius="${wheel_radius}" length="${wheel_width}"/>
            </geometry>
        </collision>
    </link>
    <link name="fr_wheel">
        <inertial>
            <origin xyz="1.7993153811346474e-09 0.0 -0" rpy="0.0 -0.0 0.0" />
            <mass value="0.1449437592188408" />
            <inertia ixx="0.00010654272201079539" iyy="0.00010654272201079994" izz="0.00017047197881125639" ixy="4.7460314825842516e-20" iyz="-5.1880768019325896e-20" ixz="0.0" />
        </inertial>
        <visual name="fr_wheel_visual">
            <origin xyz="1.7993155765338997e-09 0 -0" rpy="-1.5707963267948966 -1.2281842209915656e-15 -3.1554436208840444e-30" />
            <geometry>
                <mesh filename="package://omniseer_description/meshes/fr_wheel.stl" scale="0.001 0.001 0.001" />
            </geometry>
            <material name='body_mat'>
                <color rgba="${body_rgba}"/>
            </material>
        </visual>
        <collision name="fr_wheel_collision">
            <origin xyz="1.7993155765338997e-09 0 -0" rpy="0 -1.2281842209915656e-15 -3.1554436208840444e-30" />
            <geometry>
                <cylinder radius="${wheel_radius}" length="${wheel_width}"/>
            </geometry>
        </collision>
    </link>
    <link name="br_wheel">
        <inertial>
            <origin xyz="-1.7993152745532372e-09 0 -0" rpy="0.0 -0.0 0.0" />
            <mass value="0.1449437592188408" />
            <inertia ixx="0.00010654272201079539" iyy="0.00010654272201080037" izz="0.00017047197881125617" ixy="4.7460314825842516e-20" iyz="-5.1880768019325896e-20" ixz="-4.336808689942018e-19" />
        </inertial>
        <visual name="br_wheel_visual">
            <origin xyz="-1.7993150791539846e-09 0 -0" rpy="-1.5707963267948966 -1.2281842209915656e-15 -3.1554436208840444e-30" />
            <geometry>
                <mesh filename="package://omniseer_description/meshes/br_wheel.stl" scale="0.001 0.001 0.001" />
            </geometry>
            <material name='body_mat'>
                <color rgba="${body_rgba}"/>
            </material>
        </visual>
        <collision name="br_wheel_collision">
            <origin xyz="-1.7993150791539846e-09 0 -0" rpy="0 -1.2281842209915656e-15 -3.1554436208840444e-30" />
            <geometry>
                <cylinder radius="${wheel_radius}" length="${wheel_width}"/>
            </geometry>
        </collision>
    </link>
    <link name="chassis">
        <inertial>
            <origin xyz="0.015255860402233874 0.00044882299423251547 0.05333371024181444" rpy="0.0 0.0 0.0" />
            <mass value="5.320840769031529" />
            <inertia ixx="0.024460730291649475" iyy="0.051291345440382746" izz="0.042444773249914435" ixy="3.555570989810459e-05" iyz="0.00014378429529634938" ixz="0.0026756715987900814" />
        </inertial>
        <visual name="chassis_visual">
            <origin xyz="0.0 0.0 0.0" rpy="0.0 0.0 0.0" />
            <geometry>
                <mesh filename="package://omniseer_description/meshes/chassis.stl" scale="0.001 0.001 0.001" />
            </geometry>
            <material name='body_mat'>
                <color rgba="${body_rgba}"/>
            </material>
        </visual>
        <collision name="chassis_collision">
            <origin xyz="0.0 0.0 0.0" rpy="0.0 0.0 0.0" />
            <geometry>
                <mesh filename="package://omniseer_description/meshes/chassis.stl" scale="0.001 0.001 0.001" />
            </geometry>
        </collision>
    </link>
    <link name="lidar_top">
        <frame name="lidar_frame" attached_to="lidar_top">
            <pose>0 0 -0.076 0 0 0</pose>
        </frame>
        <inertial>
            <origin xyz="-2.954093418429609e-17 9.748508280817712e-16 0.009999998873493041" rpy="0.0 -0.0 0.0" />
            <mass value="0.6042068071016563" />
            <inertia ixx="0.0002051785615782703" iyy="0.0002051785615782599" izz="0.000370076669349746" ixy="9.281393431592715e-18" iyz="4.224665266698078e-18" ixz="1.2566166227386013e-18" />
        </inertial>
        <visual name="lidar_top_visual">
            <origin xyz="0.0 0.0 -0.15209671" rpy="0.0 -0.0 0.0" />
            <geometry>
                <mesh filename="package://omniseer_description/meshes/lidar_top.stl" scale="0.001 0.001 0.001" />
            </geometry>
            <material name='sensor_mat'>
                <color rgba="${sensor_rgba}"/>
            </material>
        </visual>
        <collision name="lidar_top_collision">
            <origin xyz="0.0 0.0 -0.15209671" rpy="0.0 -0.0 0.0" />
            <geometry>
                <mesh filename="package://omniseer_description/meshes/lidar_top.stl" scale="0.001 0.001 0.001" />
            </geometry>
        </collision>
    </link>
    <link name="lidar_frame"/>
    <link name="sonar_link">
        <inertial>
            <origin xyz="0 0 0" rpy="0 0 0"/>
            <mass value="0.01"/>
            <inertia
                ixx="1e-7" ixy="0.0" ixz="0.0"
                iyy="1e-7" iyz="0.0"
                izz="1e-7"/>
        </inertial>
        <visual name="sonar_viz">
            <geometry><box size="0.01 0.01 0.01"/></geometry>
            <material name='r'>
                <color rgba="${debug_rgba}"/>
            </material>
        </visual>
    </link>
    <link name="imu_link">
        <inertial>
            <origin xyz="0 0 0" rpy="0 0 0"/>
            <mass value="0.01"/>
            <inertia
                ixx="1e-7" ixy="0.0" ixz="0.0"
                iyy="1e-7" iyz="0.0"
                izz="1e-7"/>
        </inertial>
        <visual name="imu_viz">
            <geometry><box size="0.01 0.01 0.01"/></geometry>
            <material name='r'>
                <color rgba="${debug_rgba}"/>
            </material>
        </visual>
    </link>
    <link name="camera_link">
        <inertial>
            <origin xyz="0 0 0" rpy="0 0 0"/>
            <mass value="0.01"/>
            <inertia
                ixx="1e-7" ixy="0.0" ixz="0.0"
                iyy="1e-7" iyz="0.0"
                izz="1e-7"/>
        </inertial>
        <visual name="camera_viz">
            <geometry><box size="0.01 0.01 0.01"/></geometry>
            <material name='r'>
                <color rgba="${debug_rgba}"/>
            </material>
        </visual>
    </link>

    <!-- Joints -->

    <joint name="chassis_camera_joint" type="fixed">
        <parent link="chassis"/>
        <child  link="camera_link"/>
        <origin xyz="0.145 0.0 0.1248" rpy="0 0 0"/>
    </joint>
    <joint name="chassis_sonar_joint" type="fixed">
        <parent link="chassis"/>
        <child  link="sonar_link"/>
        <origin xyz="0.1775 0 0.015" rpy="0 0 0"/>
    </joint>
    <joint name="lidar_top_to_frame" type="fixed">
        <parent link="lidar_top"/>
        <child  link="lidar_frame"/>
        <origin xyz="0 0 -0.076" rpy="0 0 0"/>
    </joint>
    <joint name="chassis_imu_joint" type="fixed">
        <parent link="chassis"/>
        <child  link="imu_link"/>
        <origin xyz="0.01 0 0.045" rpy="0 0 0"/>
    </joint>
    <joint name="chassis_br_wheel_joint" type="continuous">
        <origin xyz="-0.0971 -0.10886705 8.94e-06" rpy="1.5707963267948966 -0.0 0.0" />
        <parent link="chassis" />
        <child link="br_wheel" />
        <axis xyz="0.0 0.0 -1.0" />
        <dynamics damping="0.1"/>
    </joint>
    <joint name="chassis_fr_wheel_joint" type="continuous">
        <origin xyz="0.0976 -0.10886705 8.94e-06" rpy="1.5707963267948966 -0.0 0.0" />
        <parent link="chassis" />
        <child link="fr_wheel" />
        <axis xyz="-0.0 -0.0 -1.0" />
        <dynamics damping="0.1"/>
    </joint>
    <joint name="chassis_bl_wheel_joint" type="continuous">
        <origin xyz="-0.0971 0.10886705 8.94e-06" rpy="-1.5707963267948966 -0.0 0.0" />
        <parent link="chassis" />
        <child link="bl_wheel" />
        <axis xyz="0.0 0.0 1.0" />
        <dynamics damping="0.1"/>
    </joint>
    <joint name="chassis_fl_wheel_joint" type="continuous">
        <origin xyz="0.0976 0.10886705 8.94e-06" rpy="-1.5707963267948966 -0.0 0.0" />
        <parent link="chassis" />
        <child link="fl_wheel" />
        <axis xyz="0.0 0.0 1.0" />
        <dynamics damping="0.1"/>
    </joint>
    <joint name="chassis_lidar_joint" type="fixed">
        <origin xyz="0.0 0.0 0.15209671" rpy="0.0 -0.0 0.0" />
        <parent link="chassis" />
        <child link="lidar_top" />
    </joint>
    <link name="base_link"/>
    <joint name="base_to_chassis" type="fixed">
        <parent link="base_link"/>
        <child  link="chassis"/>
        <origin xyz="0 0 0" rpy="0 0 0"/>
    </joint>

    <ros2_control name="GazeboSimSystem" type="system">
        <hardware>
            <plugin>gz_ros2_control/GazeboSimSystem</plugin>
        </hardware>

        <joint name="chassis_fl_wheel_joint">
            <command_interface name="velocity">
                <param name="min">${min_vel}</param>
                <param name="max">${max_vel}</param>
            </command_interface>
            <state_interface   name="velocity"/>
            <state_interface   name="position"/>
            <state_interface   name="effort"/>

        </joint>

        <joint name="chassis_fr_wheel_joint">
            <command_interface name="velocity">
                <param name="min">${min_vel}</param>
                <param name="max">${max_vel}</param>
            </command_interface>
            <state_interface   name="velocity"/>
            <state_interface   name="position"/>
            <state_interface   name="effort"/>
        </joint>

        <joint name="chassis_bl_wheel_joint">
            <command_interface name="velocity">
                <param name="min">${min_vel}</param>
                <param name="max">${max_vel}</param>
            </command_interface>
            <state_interface   name="velocity"/>
            <state_interface   name="position"/>
            <state_interface   name="effort"/>
        </joint>

        <joint name="chassis_br_wheel_joint">
            <command_interface name="velocity">
                <param name="min">${min_vel}</param>
                <param name="max">${max_vel}</param>
            </command_interface>
            <state_interface   name="velocity"/>
            <state_interface   name="position"/>
            <state_interface   name="effort"/>
        </joint>
    </ros2_control>

    <!-- Gazebo -->

    <gazebo reference="camera_link">
        <sensor name="front_camera" type="camera">
            <update_rate>30</update_rate>
            <always_on>1</always_on>
            <topic>front_camera/image</topic>
            <camera>
                <horizontal_fov>1.309</horizontal_fov>
                <image>
                    <width>1920</width>
                    <height>1080</height>
                    <format>R8G8B8</format>
                </image>
                <clip>
                    <near>0.03</near>
                    <far>100</far>
                </clip>
            </camera>
            <visualize>true</visualize>
        </sensor>
    </gazebo>

    <gazebo reference="sonar_link">
        <sensor name="sonar" type="gpu_lidar">
            <frame_id>sonar_link</frame_id>
            <pose>0 0 0 0 0 0</pose>
            <update_rate>20</update_rate>
            <topic>sonar</topic>
            <ray>
                <scan>
                    <horizontal>
                        <samples>21</samples>
                        <min_angle>-0.131</min_angle>
                        <max_angle> 0.131</max_angle>
                    </horizontal>
                </scan>
                <range>
                    <min>0.02</min>
                    <max>4.0</max>
                    <resolution>0.01</resolution>
                </range>
            </ray>
            <always_on>1</always_on>
            <visualize>true</visualize>
        </sensor>
    </gazebo>

    <gazebo reference="lidar_top">
        <sensor name="rplidar_a1" type="gpu_lidar">
            <frame_id>lidar_frame</frame_id>
            <pose>0 0 0 0 0 0</pose>
            <topic>lidar</topic>
            <update_rate>10</update_rate>
            <ray>
                <scan>
                    <horizontal>
                    <samples>360</samples>
                    <resolution>1</resolution>
                    <min_angle>-3.14159</min_angle>
                    <max_angle> 3.14159</max_angle>
                    </horizontal>
                </scan>
                <range>
                    <min>0.12</min>
                    <max>12.0</max>
                    <resolution>0.01</resolution>
                </range>
            </ray>
            <always_on>1</always_on>
            <visualize>true</visualize>
        </sensor>
    </gazebo>


    <gazebo reference="imu_link">
        <sensor name="imu_sensor" type="imu">
            <frame_id>imu_link</frame_id>
            <pose>0 0 0 0 0 0</pose>
            <always_on>1</always_on>
            <update_rate>200</update_rate>
            <topic>imu</topic>
            <imu>
                <angular_velocity>
                    <x><noise type="gaussian"><mean>0</mean><stddev>0.001</stddev></noise></x>
                    <y><noise type="gaussian"><mean>0</mean><stddev>0.001</stddev></noise></y>
                    <z><noise type="gaussian"><mean>0</mean><stddev>0.001</stddev></noise></z>
                </angular_velocity>

                <linear_acceleration>
                    <x><noise type="gaussian"><mean>0</mean><stddev>0.10</stddev></noise></x>
                    <y><noise type="gaussian"><mean>0</mean><stddev>0.10</stddev></noise></y>
                    <z><noise type="gaussian"><mean>0</mean><stddev>0.10</stddev></noise></z>
                </linear_acceleration>
            </imu>
        </sensor>
    </gazebo>

    <gazebo reference='fl_wheel'>
        <collision>
            <surface>
                <friction>
                    <ode>
                        <mu>${mu}</mu>
                        <mu2>${mu2}</mu2>
                        <slip1>${slip1}</slip1>
                        <slip2>${slip2}</slip2>
                        <fdir1 gz:expressed_in="base_link">1 -1 0</fdir1>
                    </ode>
                </friction>
                <contact>
                    <ode>
                        <kp>${kp}</kp>
                        <kd>${kd}</kd>
                    </ode>
                </contact>
            </surface>
        </collision>
    </gazebo>
    <gazebo reference='fr_wheel'>
        <collision>
            <surface>
                <friction>
                <ode>
                    <mu>${mu}</mu>
                    <mu2>${mu2}</mu2>
                    <slip1>${slip1}</slip1>
                    <slip2>${slip2}</slip2>
                    <fdir1 gz:expressed_in="base_link">1 1 0</fdir1>
                </ode>
                </friction>
                <contact>
                    <ode>
                        <kp>${kp}</kp>
                        <kd>${kd}</kd>
                    </ode>
                </contact>
            </surface>
        </collision>
    </gazebo>
    <gazebo reference='bl_wheel'>
        <collision>
            <surface>
                <friction>
                    <ode>
                        <mu>${mu}</mu>
                        <mu2>${mu2}</mu2>
                        <slip1>${slip1}</slip1>
                        <slip2>${slip2}</slip2>
                        <fdir1 gz:expressed_in="base_link">1 1 0</fdir1>
                    </ode>
                </friction>
                <contact>
                    <ode>
                        <kp>${kp}</kp>
                        <kd>${kd}</kd>
                    </ode>
                </contact>
            </surface>
        </collision>
    </gazebo>
    <gazebo reference='br_wheel'>
        <collision>
            <surface>
                <friction>
                    <ode>
                        <mu>${mu}</mu>
                        <mu2>${mu2}</mu2>
                        <slip1>${slip1}</slip1>
                        <slip2>${slip2}</slip2>
                        <fdir1 gz:expressed_in="base_link">1 -1 0</fdir1>
                    </ode>
                </friction>
                <contact>
                    <ode>
                        <kp>${kp}</kp>
                        <kd>${kd}</kd>
                    </ode>
                </contact>
            </surface>
        </collision>
    </gazebo>

    <gazebo>
        <plugin name="gz_ros2_control::GazeboSimROS2ControlPlugin" filename="libgz_ros2_control-system">
            <verbose>true</verbose>
            <parameters>$(find bringup)/config/controllers.yaml</parameters>
            <param name="config_file" value="$(find bringup)/config/controllers.yaml"/>
            <controller_manager_prefix_node_name>controller_manager</controller_manager_prefix_node_name>
        </plugin>
    </gazebo>

    <gazebo>
        <plugin name="gz::sim::systems::OdometryPublisher" filename="gz-sim-odometry-publisher-system">
            <dimensions>3</dimensions>
            <odom_publish_frequency>50</odom_publish_frequency>
            <odom_topic>/model_odom</odom_topic>
            <odom_frame>odom</odom_frame>
            <robot_base_frame>base_link</robot_base_frame>
        </plugin>
    </gazebo>
</robot>
