<?xml version="1.0" ?>
<sdf version="1.11">
  <model name="robot_v1">
    <link name="base_link">
      <inertial>
        <mass>0.0001</mass>
        <inertia>
          <ixx>1e-09</ixx>
          <ixy>0</ixy>
          <ixz>0</ixz>
          <iyy>1e-09</iyy>
          <iyz>0</iyz>
          <izz>1e-09</izz>
        </inertia>
      </inertial>
    </link>
    <link name="fl_wheel_1">
      <pose relative_to="__model__">0.09760000179931552 0.10761705076677833 8.938861234365387e-06 -1.4216528736923893e-29 3.1554436208840444e-30 -1.2281842209915656e-15</pose>
      <inertial>
        <mass>0.1449437592188408</mass>
        <inertia>
          <ixx>0.0001065427220107956</ixx>
          <ixy>0.0</ixy>
          <ixz>4.7460314825842516e-20</ixz>
          <iyy>0.00017047197881125617</iyy>
          <iyz>5.190723779892759e-20</iyz>
          <izz>0.00010654272201080081</izz>
        </inertia>
      </inertial>
      <visual name="fl_wheel_1__body1_visual">
        <geometry>
          <mesh>
            <scale>0.01 0.01 0.01</scale>
            <uri>meshes/fl_wheel_1/body1_visual.obj</uri>
          </mesh>
        </geometry>
      </visual>
      <collision name="fl_wheel_1__body1_collision">
        <pose relative_to="__model__">0.09760000179931533 0.10761705076677833 8.937736196799052e-06 -0.0 -1.5707963267948966 0</pose>
        <geometry>
          <box>
            <size>0.09699999999999999 0.041999999999999996 0.09699999999999999</size>
          </box>
        </geometry>
      </collision>
    </link>
    <link name="bl_wheel_1"><?xml version="1.0" ?>
<sdf version="1.11">
  <model name="robot_v1">
    <link name="base_link">
      <inertial>
        <mass>0.0001</mass>
        <inertia>
          <ixx>1e-09</ixx>
          <ixy>0</ixy>
          <ixz>0</ixz>
          <iyy>1e-09</iyy>
          <iyz>0</iyz>
          <izz>1e-09</izz>
        </inertia>
      </inertial>
    </link>
    <link name="fl_wheel_1">
      <pose relative_to="__model__">0.09760000179931552 0.10761705076677833 8.938861234365387e-06 -1.4216528736923893e-29 3.1554436208840444e-30 -1.2281842209915656e-15</pose>
      <inertial>
        <mass>0.1449437592188408</mass>
        <inertia>
          <ixx>0.0001065427220107956</ixx>
          <ixy>0.0</ixy>
          <ixz>4.7460314825842516e-20</ixz>
          <iyy>0.00017047197881125617</iyy>
          <iyz>5.190723779892759e-20</iyz>
          <izz>0.00010654272201080081</izz>
        </inertia>
      </inertial>
      <visual name="fl_wheel_1__body1_visual">
        <geometry>
          <mesh>
            <scale>0.01 0.01 0.01</scale>
            <uri>meshes/fl_wheel_1/body1_visual.obj</uri>
          </mesh>
        </geometry>
      </visual>
      <collision name="fl_wheel_1__body1_collision">
        <pose relative_to="__model__">0.09760000179931533 0.10761705076677833 8.937736196799052e-06 -0.0 -1.5707963267948966 0</pose>
        <geometry>
          <box>
            <size>0.09699999999999999 0.041999999999999996 0.09699999999999999</size>
          </box>
        </geometry>
      </collision>
    </link>
    <link name="bl_wheel_1">
      <pose relative_to="__model__">-0.09710000179931515 0.10761705076677833 8.938861234365387e-06 -1.4216528736923893e-29 3.1554436208840444e-30 -1.2281842209915656e-15</pose>
      <inertial>
        <mass>0.1449437592188408</mass>
        <inertia>
          <ixx>0.0001065427220107956</ixx>
          <ixy>2.168404344971009e-19</ixy>
          <ixz>4.743384504624082e-20</ixz>
          <iyy>0.00017047197881125617</iyy>
          <iyz>5.190723779892759e-20</iyz>
          <izz>0.00010654272201080037</izz>
        </inertia>
      </inertial>
      <visual name="bl_wheel_1__body1_visual">
        <geometry>
          <mesh>
            <scale>0.01 0.01 0.01</scale>
            <uri>meshes/bl_wheel_1/body1_visual.obj</uri>
          </mesh>
        </geometry>
      </visual>
      <collision name="bl_wheel_1__body1_collision">
        <pose relative_to="__model__">-0.09710000179931534 0.10761705076677833 8.937736196799052e-06 -0.0 -1.5707963267948966 0</pose>
        <geometry>
          <box>
            <size>0.09699999999999999 0.041999999999999996 0.09699999999999999</size>
          </box>
        </geometry>
      </collision>
    </link>
    <link name="fr_wheel_1">
      <pose relative_to="__model__">0.09760000179931558 -0.10761705076677823 8.938861234365387e-06 -1.4216528736923893e-29 3.1554436208840444e-30 -1.2281842209915656e-15</pose>
      <inertial>
        <mass>0.1449437592188408</mass>
        <inertia>
          <ixx>0.0001065427220107956</ixx>
          <ixy>0.0</ixy>
          <ixz>4.7460314825842516e-20</ixz>
          <iyy>0.00017047197881125617</iyy>
          <iyz>5.1880768019325896e-20</iyz>
          <izz>0.00010654272201079994</izz>
        </inertia>
      </inertial>
      <visual name="fr_wheel_1__body1_visual">
        <geometry>
          <mesh>
            <scale>0.01 0.01 0.01</scale>
            <uri>meshes/fr_wheel_1/body1_visual.obj</uri>
          </mesh>
        </geometry>
      </visual>
      <collision name="fr_wheel_1__body1_collision">
        <pose relative_to="__model__">0.09760000179931538 -0.10761705076677823 8.937736196799052e-06 -0.0 -1.5707963267948966 0</pose>
        <geometry>
          <box>
            <size>0.09699999999999999 0.041999999999999996 0.09699999999999999</size>
          </box>
        </geometry>
      </collision>
    </link>
    <link name="br_wheel_1">
      <pose relative_to="__model__">-0.09710000179931509 -0.10761705076677823 8.938861234365387e-06 -1.4216528736923893e-29 3.1554436208840444e-30 -1.2281842209915656e-15</pose>
      <inertial>
        <mass>0.1449437592188408</mass>
        <inertia>
          <ixx>0.0001065427220107956</ixx>
          <ixy>0.0</ixy>
          <ixz>4.7460314825842516e-20</ixz>
          <iyy>0.00017047197881125617</iyy>
          <iyz>5.1880768019325896e-20</iyz>
          <izz>0.00010654272201079994</izz>
        </inertia>
      </inertial>
      <visual name="br_wheel_1__body1_visual">
        <geometry>
          <mesh>
            <scale>0.01 0.01 0.01</scale>
            <uri>meshes/br_wheel_1/body1_visual.obj</uri>
          </mesh>
        </geometry>
      </visual>
      <collision name="br_wheel_1__body1_collision">
        <pose relative_to="__model__">-0.09710000179931529 -0.10761705076677823 8.937736196799052e-06 -0.0 -1.5707963267948966 0</pose>
        <geometry>
          <box>
            <size>0.09699999999999999 0.041999999999999996 0.09699999999999999</size>
          </box>
        </geometry>
      </collision>
    </link>
    <link name="base_link_1">
      <inertial>
        <pose>0.015255860402233874 0.00044882299423251547 0.05333371024181444 0.0 -0.0 0.0</pose>
        <mass>5.320840769031529</mass>
        <inertia>
          <ixx>0.02446073029164947</ixx>
          <ixy>3.555570989810459e-05</ixy>
          <ixz>0.0026756715987900814</ixz>
          <iyy>0.051291345440382746</iyy>
          <iyz>0.00014378429529634938</iyz>
          <izz>0.042444773249914435</izz>
        </inertia>
      </inertial>
      <visual name="base_link_1__chassis_visual">
        <geometry>
          <mesh>
            <scale>0.01 0.01 0.01</scale>
            <uri>meshes/base_link_1/chassis_visual.obj</uri>
          </mesh>
        </geometry>
      </visual>
      <visual name="base_link_1__powerbank_visual">
        <geometry>
          <mesh>
            <scale>0.01 0.01 0.01</scale>
            <uri>meshes/base_link_1/powerbank_visual.obj</uri>
          </mesh>
        </geometry>
      </visual>
      <visual name="base_link_1__battery_visual">
        <geometry>
          <mesh>
            <scale>0.01 0.01 0.01</scale>
            <uri>meshes/base_link_1/battery_visual.obj</uri>
          </mesh>
        </geometry>
      </visual>
      <visual name="base_link_1__bl_motor_visual">
        <geometry>
          <mesh>
            <scale>0.01 0.01 0.01</scale>
            <uri>meshes/base_link_1/bl_motor_visual.obj</uri>
          </mesh>
        </geometry>
      </visual>
      <visual name="base_link_1__br_motor_visual">
        <geometry>
          <mesh>
            <scale>0.01 0.01 0.01</scale>
            <uri>meshes/base_link_1/br_motor_visual.obj</uri>
          </mesh>
        </geometry>
      </visual>
      <visual name="base_link_1__fl_motor_visual">
        <geometry>
          <mesh>
            <scale>0.01 0.01 0.01</scale>
            <uri>meshes/base_link_1/fl_motor_visual.obj</uri>
          </mesh>
        </geometry>
      </visual>
      <visual name="base_link_1__fr_motor_visual">
        <geometry>
          <mesh>
            <scale>0.01 0.01 0.01</scale>
            <uri>meshes/base_link_1/fr_motor_visual.obj</uri>
          </mesh>
        </geometry>
      </visual>
      <visual name="base_link_1__hs_visual">
        <geometry>
          <mesh>
            <scale>0.01 0.01 0.01</scale>
            <uri>meshes/base_link_1/hs_visual.obj</uri>
          </mesh>
        </geometry>
      </visual>
      <visual name="base_link_1__imu_visual">
        <geometry>
          <mesh>
            <scale>0.01 0.01 0.01</scale>
            <uri>meshes/base_link_1/imu_visual.obj</uri>
          </mesh>
        </geometry>
      </visual>
      <visual name="base_link_1__upper_plate_visual">
        <geometry>
          <mesh>
            <scale>0.01 0.01 0.01</scale>
            <uri>meshes/base_link_1/upper_plate_visual.obj</uri>
          </mesh>
        </geometry>
      </visual>
      <visual name="base_link_1__camera_visual">
        <geometry>
          <mesh>
            <scale>0.01 0.01 0.01</scale>
            <uri>meshes/base_link_1/camera_visual.obj</uri>
          </mesh>
        </geometry>
      </visual>
      <visual name="base_link_1__lidar_body_visual">
        <geometry>
          <mesh>
            <scale>0.01 0.01 0.01</scale>
            <uri>meshes/base_link_1/lidar_body_visual.obj</uri>
          </mesh>
        </geometry>
      </visual>
      <collision name="base_link_1__chassis_collision">
        <pose relative_to="__model__">0.0 0.0 0.011096708873493042 -0.0 -1.5707963267948966 0</pose>
        <geometry>
          <box>
            <size>0.05 0.14500000688713044 0.2969975141066243</size>
          </box>
        </geometry>
      </collision>
      <collision name="base_link_1__powerbank_collision">
        <pose relative_to="__model__">0.0004999982006848214 -0.030382949210869984 0.0033422814465520513 -0.0 -1.5707963267948966 0</pose>
        <geometry>
          <box>
            <size>0.029000000000000005 0.071 0.11000000000000001</size>
          </box>
        </geometry>
      </collision>
      <collision name="base_link_1__battery_collision">
        <pose relative_to="__model__">0.000499998200684928 0.03961705078913 0.001342281446551261 -0.0 -1.5707963267948966 0</pose>
        <geometry>
          <box>
            <size>0.025 0.045 0.135</size>
          </box>
        </geometry>
      </collision>
      <collision name="base_link_1__bl_motor_collision">
        <pose relative_to="__model__">-0.09710000179931542 0.050017050766778225 0.0070089377361969765 -0.0 -1.5707963267948966 0</pose>
        <geometry>
          <box>
            <size>0.037000000000000005 0.07320000000000014 0.03699999999999999</size>
          </box>
        </geometry>
      </collision>
      <collision name="base_link_1__br_motor_collision">
        <pose relative_to="__model__">-0.09710000179931542 -0.050017050766778225 0.0070089377361969765 -0.0 -1.5707963267948966 0</pose>
        <geometry>
          <box>
            <size>0.037000000000000005 0.07320000000000014 0.03699999999999999</size>
          </box>
        </geometry>
      </collision>
      <collision name="base_link_1__fl_motor_collision">
        <pose relative_to="__model__">0.09760000179931541 0.050017050766778225 0.0070089377361969765 -0.0 -1.5707963267948966 0</pose>
        <geometry>
          <box>
            <size>0.037000000000000005 0.07320000000000014 0.03699999999999999</size>
          </box>
        </geometry>
      </collision>
      <collision name="base_link_1__fr_motor_collision">
        <pose relative_to="__model__">0.09760000179931541 -0.050017050766778225 0.0070089377361969765 -0.0 -1.5707963267948966 0</pose>
        <geometry>
          <box>
            <size>0.037000000000000005 0.07320000000000014 0.03699999999999999</size>
          </box>
        </geometry>
      </collision>
      <collision name="base_link_1__hs_collision">
        <pose relative_to="__model__">0.16424875705331196 -4.473035630434552e-06 0.00630893883889007 -0.0 -1.5707963267948966 0</pose>
        <geometry>
          <box>
            <size>0.03400000000000001 0.06475 0.032500000000000036</size>
          </box>
        </geometry>
      </collision>
      <collision name="base_link_1__imu_collision">
        <pose relative_to="__model__">0.010000000000000002 8.881784197001253e-18 0.04284670887349312 -0.0 -1.5707963267948966 0</pose>
        <geometry>
          <box>
            <size>0.013499999999999996 0.026499999999999985 0.020000000000000004</size>
          </box>
        </geometry>
      </collision>
      <collision name="base_link_1__upper_plate_collision">
        <pose relative_to="__model__">-7.105427357601002e-16 9.237055564881303e-16 0.07109670887349191 -0.0 -1.5707963267948966 0</pose>
        <geometry>
          <box>
            <size>0.0699999999999978 0.132 0.257</size>
          </box>
        </geometry>
      </collision>
      <collision name="base_link_1__camera_collision">
        <pose relative_to="__model__">0.1384999999999989 1.0369483049998962e-15 0.12409670887349437 -0.0 -1.5707963267948966 0</pose>
        <geometry>
          <box>
            <size>0.03600000000000001 0.036000000536441805 0.020000000000000177</size>
          </box>
        </geometry>
      </collision>
      <collision name="base_link_1__lidar_body_collision">
        <pose relative_to="__model__">-5.3734794391857575e-16 5.151434834260726e-16 0.12909670887349262 -0.0 -1.5707963267948966 0</pose>
        <geometry>
          <box>
            <size>0.04600000000000001 0.07 0.07</size>
          </box>
        </geometry>
      </collision>
    </link>
    <link name="lidar_top_1">
      <inertial>
        <pose>-2.954093418429609e-17 9.748508280817712e-16 0.16209670887349303 0.0 -0.0 0.0</pose>
        <mass>0.6042068071016563</mass>
        <inertia>
          <ixx>0.0002051785615782703</ixx>
          <ixy>9.281393431592714e-18</ixy>
          <ixz>1.2566166227386013e-18</ixz>
          <iyy>0.0002051785615782599</iyy>
          <iyz>4.224665266698078e-18</iyz>
          <izz>0.000370076669349746</izz>
        </inertia>
      </inertial>
      <visual name="lidar_top_1__body1_visual">
        <geometry>
          <mesh>
            <scale>0.01 0.01 0.01</scale>
            <uri>meshes/lidar_top_1/body1_visual.obj</uri>
          </mesh>
        </geometry>
      </visual>
      <collision name="lidar_top_1__body1_collision">
        <pose relative_to="__model__">-7.727152251391089e-16 7.416289804496045e-16 0.16209670887349262 -0.0 -1.5707963267948966 0</pose>
        <geometry>
          <box>
            <size>0.019999999999999983 0.07 0.07</size>
          </box>
        </geometry>
      </collision>
    </link>
    <joint name="revolute_16" type="continuous">
      <pose relative_to="__model__">-0.09710000179931534 -0.08661705076677828 8.937736196800161e-06 0.0 -0.0 0.0</pose>
      <parent>base_link_1</parent>
      <child>br_wheel_1</child>
      <axis>
        <xyz expressed_in="__model__">1.2698175844150216e-15 -1.0 -1.1018963519404669e-14</xyz>
      </axis>
    </joint>
    <joint name="revolute_17" type="continuous">
      <pose relative_to="__model__">0.09760000179931533 -0.08661705076677828 8.937736196800161e-06 0.0 -0.0 0.0</pose>
      <parent>base_link_1</parent>
      <child>fr_wheel_1</child>
      <axis>
        <xyz expressed_in="__model__">-1.2698175844150216e-15 -1.0 -1.1018963519404669e-14</xyz>
      </axis>
    </joint>
    <joint name="revolute_18" type="continuous">
      <pose relative_to="__model__">-0.09710000179931534 0.08661705076677828 8.937736196800161e-06 0.0 -0.0 0.0</pose>
      <parent>base_link_1</parent>
      <child>bl_wheel_1</child>
      <axis>
        <xyz expressed_in="__model__">1.2698175844150216e-15 1.0 -1.1018963519404669e-14</xyz>
      </axis>
    </joint>
    <joint name="revolute_19" type="continuous">
      <pose relative_to="__model__">0.09760000179931533 0.08661705076677828 8.937736196800161e-06 0.0 -0.0 0.0</pose>
      <parent>base_link_1</parent>
      <child>fl_wheel_1</child>
      <axis>
        <xyz expressed_in="__model__">-1.2698175844150216e-15 1.0 -1.1018963519404669e-14</xyz>
      </axis>
    </joint>
    <joint name="revolute_22" type="continuous">
      <pose relative_to="__model__">-5.3734794391857575e-16 5.151434834260726e-16 0.15209670887349305 0.0 -0.0 0.0</pose>
      <parent>base_link_1</parent>
      <child>lidar_top_1</child>
      <axis>
        <xyz expressed_in="__model__">-1.1679893163751825e-14 1.1241008124329724e-14 1.0</xyz>
      </axis>
    </joint>
    <joint name="base_link_joint" type="fixed">
      <parent>base_link</parent>
      <child>base_link_1</child>
      <axis/>
    </joint>
  </model>
</sdf>

      <pose relative_to="__model__">-0.09710000179931515 0.10761705076677833 8.938861234365387e-06 -1.4216528736923893e-29 3.1554436208840444e-30 -1.2281842209915656e-15</pose>
      <inertial>
        <mass>0.1449437592188408</mass>
        <inertia>
          <ixx>0.0001065427220107956</ixx>
          <ixy>2.168404344971009e-19</ixy>
          <ixz>4.743384504624082e-20</ixz>
          <iyy>0.00017047197881125617</iyy>
          <iyz>5.190723779892759e-20</iyz>
          <izz>0.00010654272201080037</izz>
        </inertia>
      </inertial>
      <visual name="bl_wheel_1__body1_visual">
        <geometry>
          <mesh>
            <scale>0.01 0.01 0.01</scale>
            <uri>meshes/bl_wheel_1/body1_visual.obj</uri>
          </mesh>
        </geometry>
      </visual>
      <collision name="bl_wheel_1__body1_collision">
        <pose relative_to="__model__">-0.09710000179931534 0.10761705076677833 8.937736196799052e-06 -0.0 -1.5707963267948966 0</pose>
        <geometry>
          <box>
            <size>0.09699999999999999 0.041999999999999996 0.09699999999999999</size>
          </box>
        </geometry>
      </collision>
    </link>
    <link name="fr_wheel_1">
      <pose relative_to="__model__">0.09760000179931558 -0.10761705076677823 8.938861234365387e-06 -1.4216528736923893e-29 3.1554436208840444e-30 -1.2281842209915656e-15</pose>
      <inertial>
        <mass>0.1449437592188408</mass>
        <inertia>
          <ixx>0.0001065427220107956</ixx>
          <ixy>0.0</ixy>
          <ixz>4.7460314825842516e-20</ixz>
          <iyy>0.00017047197881125617</iyy>
          <iyz>5.1880768019325896e-20</iyz>
          <izz>0.00010654272201079994</izz>
        </inertia>
      </inertial>
      <visual name="fr_wheel_1__body1_visual">
        <geometry>
          <mesh>
            <scale>0.01 0.01 0.01</scale>
            <uri>meshes/fr_wheel_1/body1_visual.obj</uri>
          </mesh>
        </geometry>
      </visual>
      <collision name="fr_wheel_1__body1_collision">
        <pose relative_to="__model__">0.09760000179931538 -0.10761705076677823 8.937736196799052e-06 -0.0 -1.5707963267948966 0</pose>
        <geometry>
          <box>
            <size>0.09699999999999999 0.041999999999999996 0.09699999999999999</size>
          </box>
        </geometry>
      </collision>
    </link>
    <link name="br_wheel_1">
      <pose relative_to="__model__">-0.09710000179931509 -0.10761705076677823 8.938861234365387e-06 -1.4216528736923893e-29 3.1554436208840444e-30 -1.2281842209915656e-15</pose>
      <inertial>
        <mass>0.1449437592188408</mass>
        <inertia>
          <ixx>0.0001065427220107956</ixx>
          <ixy>0.0</ixy>
          <ixz>4.7460314825842516e-20</ixz>
          <iyy>0.00017047197881125617</iyy>
          <iyz>5.1880768019325896e-20</iyz>
          <izz>0.00010654272201079994</izz>
        </inertia>
      </inertial>
      <visual name="br_wheel_1__body1_visual">
        <geometry>
          <mesh>
            <scale>0.01 0.01 0.01</scale>
            <uri>meshes/br_wheel_1/body1_visual.obj</uri>
          </mesh>
        </geometry>
      </visual>
      <collision name="br_wheel_1__body1_collision">
        <pose relative_to="__model__">-0.09710000179931529 -0.10761705076677823 8.937736196799052e-06 -0.0 -1.5707963267948966 0</pose>
        <geometry>
          <box>
            <size>0.09699999999999999 0.041999999999999996 0.09699999999999999</size>
          </box>
        </geometry>
      </collision>
    </link>
    <link name="base_link_1">
      <inertial>
        <pose>0.015255860402233874 0.00044882299423251547 0.05333371024181444 0.0 -0.0 0.0</pose>
        <mass>5.320840769031529</mass>
        <inertia>
          <ixx>0.02446073029164947</ixx>
          <ixy>3.555570989810459e-05</ixy>
          <ixz>0.0026756715987900814</ixz>
          <iyy>0.051291345440382746</iyy>
          <iyz>0.00014378429529634938</iyz>
          <izz>0.042444773249914435</izz>
        </inertia>
      </inertial>
      <visual name="base_link_1__chassis_visual">
        <geometry>
          <mesh>
            <scale>0.01 0.01 0.01</scale>
            <uri>meshes/base_link_1/chassis_visual.obj</uri>
          </mesh>
        </geometry>
      </visual>
      <visual name="base_link_1__powerbank_visual">
        <geometry>
          <mesh>
            <scale>0.01 0.01 0.01</scale>
            <uri>meshes/base_link_1/powerbank_visual.obj</uri>
          </mesh>
        </geometry>
      </visual>
      <visual name="base_link_1__battery_visual">
        <geometry>
          <mesh>
            <scale>0.01 0.01 0.01</scale>
            <uri>meshes/base_link_1/battery_visual.obj</uri>
          </mesh>
        </geometry>
      </visual>
      <visual name="base_link_1__bl_motor_visual">
        <geometry>
          <mesh>
            <scale>0.01 0.01 0.01</scale>
            <uri>meshes/base_link_1/bl_motor_visual.obj</uri>
          </mesh>
        </geometry>
      </visual>
      <visual name="base_link_1__br_motor_visual">
        <geometry>
          <mesh>
            <scale>0.01 0.01 0.01</scale>
            <uri>meshes/base_link_1/br_motor_visual.obj</uri>
          </mesh>
        </geometry>
      </visual>
      <visual name="base_link_1__fl_motor_visual">
        <geometry>
          <mesh>
            <scale>0.01 0.01 0.01</scale>
            <uri>meshes/base_link_1/fl_motor_visual.obj</uri>
          </mesh>
        </geometry>
      </visual>
      <visual name="base_link_1__fr_motor_visual">
        <geometry>
          <mesh>
            <scale>0.01 0.01 0.01</scale>
            <uri>meshes/base_link_1/fr_motor_visual.obj</uri>
          </mesh>
        </geometry>
      </visual>
      <visual name="base_link_1__hs_visual">
        <geometry>
          <mesh>
            <scale>0.01 0.01 0.01</scale>
            <uri>meshes/base_link_1/hs_visual.obj</uri>
          </mesh>
        </geometry>
      </visual>
      <visual name="base_link_1__imu_visual">
        <geometry>
          <mesh>
            <scale>0.01 0.01 0.01</scale>
            <uri>meshes/base_link_1/imu_visual.obj</uri>
          </mesh>
        </geometry>
      </visual>
      <visual name="base_link_1__upper_plate_visual">
        <geometry>
          <mesh>
            <scale>0.01 0.01 0.01</scale>
            <uri>meshes/base_link_1/upper_plate_visual.obj</uri>
          </mesh>
        </geometry>
      </visual>
      <visual name="base_link_1__camera_visual">
        <geometry>
          <mesh>
            <scale>0.01 0.01 0.01</scale>
            <uri>meshes/base_link_1/camera_visual.obj</uri>
          </mesh>
        </geometry>
      </visual>
      <visual name="base_link_1__lidar_body_visual">
        <geometry>
          <mesh>
            <scale>0.01 0.01 0.01</scale>
            <uri>meshes/base_link_1/lidar_body_visual.obj</uri>
          </mesh>
        </geometry>
      </visual>
      <collision name="base_link_1__chassis_collision">
        <pose relative_to="__model__">0.0 0.0 0.011096708873493042 -0.0 -1.5707963267948966 0</pose>
        <geometry>
          <box>
            <size>0.05 0.14500000688713044 0.2969975141066243</size>
          </box>
        </geometry>
      </collision>
      <collision name="base_link_1__powerbank_collision">
        <pose relative_to="__model__">0.0004999982006848214 -0.030382949210869984 0.0033422814465520513 -0.0 -1.5707963267948966 0</pose>
        <geometry>
          <box>
            <size>0.029000000000000005 0.071 0.11000000000000001</size>
          </box>
        </geometry>
      </collision>
      <collision name="base_link_1__battery_collision">
        <pose relative_to="__model__">0.000499998200684928 0.03961705078913 0.001342281446551261 -0.0 -1.5707963267948966 0</pose>
        <geometry>
          <box>
            <size>0.025 0.045 0.135</size>
          </box>
        </geometry>
      </collision>
      <collision name="base_link_1__bl_motor_collision">
        <pose relative_to="__model__">-0.09710000179931542 0.050017050766778225 0.0070089377361969765 -0.0 -1.5707963267948966 0</pose>
        <geometry>
          <box>
            <size>0.037000000000000005 0.07320000000000014 0.03699999999999999</size>
          </box>
        </geometry>
      </collision>
      <collision name="base_link_1__br_motor_collision">
        <pose relative_to="__model__">-0.09710000179931542 -0.050017050766778225 0.0070089377361969765 -0.0 -1.5707963267948966 0</pose>
        <geometry>
          <box>
            <size>0.037000000000000005 0.07320000000000014 0.03699999999999999</size>
          </box>
        </geometry>
      </collision>
      <collision name="base_link_1__fl_motor_collision">
        <pose relative_to="__model__">0.09760000179931541 0.050017050766778225 0.0070089377361969765 -0.0 -1.5707963267948966 0</pose>
        <geometry>
          <box>
            <size>0.037000000000000005 0.07320000000000014 0.03699999999999999</size>
          </box>
        </geometry>
      </collision>
      <collision name="base_link_1__fr_motor_collision">
        <pose relative_to="__model__">0.09760000179931541 -0.050017050766778225 0.0070089377361969765 -0.0 -1.5707963267948966 0</pose>
        <geometry>
          <box>
            <size>0.037000000000000005 0.07320000000000014 0.03699999999999999</size>
          </box>
        </geometry>
      </collision>
      <collision name="base_link_1__hs_collision">
        <pose relative_to="__model__">0.16424875705331196 -4.473035630434552e-06 0.00630893883889007 -0.0 -1.5707963267948966 0</pose>
        <geometry>
          <box>
            <size>0.03400000000000001 0.06475 0.032500000000000036</size>
          </box>
        </geometry>
      </collision>
      <collision name="base_link_1__imu_collision">
        <pose relative_to="__model__">0.010000000000000002 8.881784197001253e-18 0.04284670887349312 -0.0 -1.5707963267948966 0</pose>
        <geometry>
          <box>
            <size>0.013499999999999996 0.026499999999999985 0.020000000000000004</size>
          </box>
        </geometry>
      </collision>
      <collision name="base_link_1__upper_plate_collision">
        <pose relative_to="__model__">-7.105427357601002e-16 9.237055564881303e-16 0.07109670887349191 -0.0 -1.5707963267948966 0</pose>
        <geometry>
          <box>
            <size>0.0699999999999978 0.132 0.257</size>
          </box>
        </geometry>
      </collision>
      <collision name="base_link_1__camera_collision">
        <pose relative_to="__model__">0.1384999999999989 1.0369483049998962e-15 0.12409670887349437 -0.0 -1.5707963267948966 0</pose>
        <geometry>
          <box>
            <size>0.03600000000000001 0.036000000536441805 0.020000000000000177</size>
          </box>
        </geometry>
      </collision>
      <collision name="base_link_1__lidar_body_collision">
        <pose relative_to="__model__">-5.3734794391857575e-16 5.151434834260726e-16 0.12909670887349262 -0.0 -1.5707963267948966 0</pose>
        <geometry>
          <box>
            <size>0.04600000000000001 0.07 0.07</size>
          </box>
        </geometry>
      </collision>
    </link>
    <link name="lidar_top_1">
      <inertial>
        <pose>-2.954093418429609e-17 9.748508280817712e-16 0.16209670887349303 0.0 -0.0 0.0</pose>
        <mass>0.6042068071016563</mass>
        <inertia>
          <ixx>0.0002051785615782703</ixx>
          <ixy>9.281393431592714e-18</ixy>
          <ixz>1.2566166227386013e-18</ixz>
          <iyy>0.0002051785615782599</iyy>
          <iyz>4.224665266698078e-18</iyz>
          <izz>0.000370076669349746</izz>
        </inertia>
      </inertial>
      <visual name="lidar_top_1__body1_visual">
        <geometry>
          <mesh>
            <scale>0.01 0.01 0.01</scale>
            <uri>meshes/lidar_top_1/body1_visual.obj</uri>
          </mesh>
        </geometry>
      </visual>
      <collision name="lidar_top_1__body1_collision">
        <pose relative_to="__model__">-7.727152251391089e-16 7.416289804496045e-16 0.16209670887349262 -0.0 -1.5707963267948966 0</pose>
        <geometry>
          <box>
            <size>0.019999999999999983 0.07 0.07</size>
          </box>
        </geometry>
      </collision>
    </link>
    <joint name="revolute_16" type="continuous">
      <pose relative_to="__model__">-0.09710000179931534 -0.08661705076677828 8.937736196800161e-06 0.0 -0.0 0.0</pose>
      <parent>base_link_1</parent>
      <child>br_wheel_1</child>
      <axis>
        <xyz expressed_in="__model__">1.2698175844150216e-15 -1.0 -1.1018963519404669e-14</xyz>
      </axis>
    </joint>
    <joint name="revolute_17" type="continuous">
      <pose relative_to="__model__">0.09760000179931533 -0.08661705076677828 8.937736196800161e-06 0.0 -0.0 0.0</pose>
      <parent>base_link_1</parent>
      <child>fr_wheel_1</child>
      <axis>
        <xyz expressed_in="__model__">-1.2698175844150216e-15 -1.0 -1.1018963519404669e-14</xyz>
      </axis>
    </joint>
    <joint name="revolute_18" type="continuous">
      <pose relative_to="__model__">-0.09710000179931534 0.08661705076677828 8.937736196800161e-06 0.0 -0.0 0.0</pose>
      <parent>base_link_1</parent>
      <child>bl_wheel_1</child>
      <axis>
        <xyz expressed_in="__model__">1.2698175844150216e-15 1.0 -1.1018963519404669e-14</xyz>
      </axis>
    </joint>
    <joint name="revolute_19" type="continuous">
      <pose relative_to="__model__">0.09760000179931533 0.08661705076677828 8.937736196800161e-06 0.0 -0.0 0.0</pose>
      <parent>base_link_1</parent>
      <child>fl_wheel_1</child>
      <axis>
        <xyz expressed_in="__model__">-1.2698175844150216e-15 1.0 -1.1018963519404669e-14</xyz>
      </axis>
    </joint>
    <joint name="revolute_22" type="continuous">
      <pose relative_to="__model__">-5.3734794391857575e-16 5.151434834260726e-16 0.15209670887349305 0.0 -0.0 0.0</pose>
      <parent>base_link_1</parent>
      <child>lidar_top_1</child>
      <axis>
        <xyz expressed_in="__model__">-1.1679893163751825e-14 1.1241008124329724e-14 1.0</xyz>
      </axis>
    </joint>
    <joint name="base_link_joint" type="fixed">
      <parent>base_link</parent>
      <child>base_link_1</child>
      <axis/>
    </joint>
  </model>
</sdf>
